2021-05-07T14:07:35|CRITICAL|root|Unhandled exception:Traceback (most recent call last):
  File "C:\Users\LAB\Anaconda3\envs\scopefoundry\lib\site-packages\ScopeFoundry\measurement.py", line 25, in run
    self.measurement._thread_run()
  File "C:\Users\LAB\Anaconda3\envs\scopefoundry\lib\site-packages\ScopeFoundry\measurement.py", line 179, in _thread_run
    self.run()
  File "C:\LabPrograms\Python\ScopeFoundryProjects\PROCHIP microscope\HexSIM_Microscope\FLIR_NI_measure.py", line 142, in run
    v0 = voltages(0,frame_idx)
TypeError: 'list' object is not callable

